Workbook

Sheet breast_cancer_experiment_result
A1: Key_Dataset | B1: Key_Run | C1: Key_Scheme | D1: Key_Scheme_options | E1: Key_Scheme_version_ID | F1: Date_time | G1: Number_of_training_instances | H1: Number_of_testing_instances | I1: Number_correct | J1: Number_incorrect | K1: Number_unclassified | L1: Percent_correct | M1: Percent_incorrect | N1: Percent_unclassified | O1: Kappa_statistic | P1: Mean_absolute_error | Q1: Root_mean_squared_error | R1: Relative_absolute_error | S1: Root_relative_squared_error | T1: SF_prior_entropy | U1: SF_scheme_entropy | V1: SF_entropy_gain | W1: SF_mean_prior_entropy | X1: SF_mean_scheme_entropy | Y1: SF_mean_entropy_gain | Z1: KB_information | AA1: KB_mean_information | AB1: KB_relative_information | AC1: True_positive_rate | AD1: Num_true_positives | AE1: False_positive_rate | AF1: Num_false_positives | AG1: True_negative_rate | AH1: Num_true_negatives | AI1: False_negative_rate | AJ1: Num_false_negatives | AK1: IR_precision | AL1: IR_recall | AM1: F_measure | AN1: Matthews_correlation | AO1: Area_under_ROC | AP1: Area_under_PRC | AQ1: Weighted_avg_true_positive_rate | AR1: Weighted_avg_false_positive_rate | AS1: Weighted_avg_true_negative_rate | AT1: Weighted_avg_false_negative_rate | AU1: Weighted_avg_IR_precision | AV1: Weighted_avg_IR_recall | AW1: Weighted_avg_F_measure | AX1: Weighted_avg_matthews_correlation | AY1: Weighted_avg_area_under_ROC | AZ1: Weighted_avg_area_under_PRC | BA1: Unweighted_macro_avg_F_measure | BB1: Unweighted_micro_avg_F_measure | BC1: Elapsed_Time_training | BD1: Elapsed_Time_testing | BE1: UserCPU_Time_training | BF1: UserCPU_Time_testing | BG1: UserCPU_Time_millis_training | BH1: UserCPU_Time_millis_testing | BI1: Serialized_Model_Size | BJ1: Serialized_Train_Set_Size | BK1: Serialized_Test_Set_Size | BL1: Coverage_of_Test_Cases_By_Regions | BM1: Size_of_Predicted_Regions | BN1: Summary | BO1: measureTreeSize | BP1: measureNumLeaves | BQ1: measureNumRules
A2: breast-cancer | B2: 1 | C2: weka.classifiers.trees.J48 | D2: '-C 0.25 -M 2' | E2: -2.1773317e+17 | F2: 20250406 | G2: 190 | H2: 96 | I2: 71 | J2: 25 | K2: 0 | L2: 73.958333 | M2: 26.041667 | N2: 0 | O2: 0.23273657 | P2: 0.36916502 | Q2: 0.47318878 | R2: 88.415407 | S2: 104.07782 | T2: 83.638867 | U2: 5444.0876 | V2: -5360.4487 | W2: 0.8712382 | X2: 56.709246 | Y2: -55.838008 | Z2: 9.0613784 | AA2: 0.094389359 | AB2: 10.833933 | AC2: 0.94117647 | AD2: 64 | AE2: 0.75 | AF2: 21 | AG2: 0.25 | AH2: 7 | AI2: 0.058823529 | AJ2: 4 | AK2: 0.75294118 | AL2: 0.94117647 | AM2: 0.83660131 | AN2: 0.27281114 | AO2: 0.56433824 | AP2: 0.73852486 | AQ2: 0.73958333 | AR2: 0.54840686 | AS2: 0.45159314 | AT2: 0.26041667 | AU2: 0.71893939 | AV2: 0.73958333 | AW2: 0.69729345 | AX2: 0.27281114 | AY2: 0.56433824 | AZ2: 0.63331662 | BA2: 0.59778783 | BB2: 0.73958333 | BC2: 0.011 | BD2: 0.002 | BE2: 0.008231 | BF2: 0.001186 | BG2: 8.231 | BH2: 1.186 | BI2: 8820 | BJ2: 23834 | BK2: 13588 | BL2: 94.791667 | BM2: 96.354167 | BN2: 'Number of leaves: 20\nSize of the tree: 24\n' | BO2: 24 | BP2: 20 | BQ2: 20
A3: breast-cancer | B3: 2 | C3: weka.classifiers.trees.J48 | D3: '-C 0.25 -M 2' | E3: -2.1773317e+17 | F3: 20250406 | G3: 188 | H3: 98 | I3: 62 | J3: 36 | K3: 0 | L3: 63.265306 | M3: 36.734694 | N3: 0 | O3: 0.11844078 | P3: 0.39525363 | Q3: 0.47669073 | R3: 94.475259 | S3: 104.42918 | T3: 85.877551 | U3: 92.387139 | V3: -6.5095876 | W3: 0.87630154 | X3: 0.94272591 | Y3: -0.066424363 | Z3: 1.1787619 | AA3: 0.012028182 | AB3: 1.3726077 | AC3: 0.73913043 | AD3: 51 | AE3: 0.62068966 | AF3: 18 | AG3: 0.37931034 | AH3: 11 | AI3: 0.26086957 | AJ3: 18 | AK3: 0.73913043 | AL3: 0.73913043 | AM3: 0.73913043 | AN3: 0.11844078 | AO3: 0.56371814 | AP3: 0.73282281 | AQ3: 0.63265306 | AR3: 0.51421228 | AS3: 0.48578772 | AT3: 0.36734694 | AU3: 0.63265306 | AV3: 0.63265306 | AW3: 0.63265306 | AX3: 0.11844078 | AY3: 0.56371814 | AZ3: 0.61471865 | BA3: 0.55922039 | BB3: 0.63265306 | BC3: 0.002 | BD3: 0.001 | BE3: 0.002213 | BF3: 0.000434 | BG3: 2.213 | BH3: 0.434 | BI3: 5348 | BJ3: 23616 | BK3: 13806 | BL3: 100 | BM3: 100 | BN3: 'Number of leaves: 3\nSize of the tree: 4\n' | BO3: 4 | BP3: 3 | BQ3: 3
A4: breast-cancer | B4: 3 | C4: weka.classifiers.trees.J48 | D4: '-C 0.25 -M 2' | E4: -2.1773317e+17 | F4: 20250406 | G4: 190 | H4: 96 | I4: 69 | J4: 27 | K4: 0 | L4: 71.875 | M4: 28.125 | N4: 0 | O4: 0.1713555 | P4: 0.36253105 | Q4: 0.46739936 | R4: 86.826562 | S4: 102.80444 | T4: 83.638867 | U4: 4368.5793 | V4: -4284.9404 | W4: 0.8712382 | X4: 45.506034 | Y4: -44.634796 | Z4: 10.414405 | AA4: 0.10848339 | AB4: 12.451633 | AC4: 0.92647059 | AD4: 63 | AE4: 0.78571429 | AF4: 22 | AG4: 0.21428571 | AH4: 6 | AI4: 0.073529412 | AJ4: 5 | AK4: 0.74117647 | AL4: 0.92647059 | AM4: 0.82352941 | AN4: 0.20086095 | AO4: 0.55829832 | AP4: 0.74933314 | AQ4: 0.71875 | AR4: 0.5779937 | AS4: 0.4220063 | AT4: 0.28125 | AU4: 0.68409091 | AV4: 0.71875 | AW4: 0.67307692 | AX4: 0.20086095 | AY4: 0.55829832 | AZ4: 0.63271601 | BA4: 0.56561086 | BB4: 0.71875 | BC4: 0.003 | BD4: 0 | BE4: 0.002176 | BF4: 0.00039 | BG4: 2.176 | BH4: 0.39 | BI4: 9524 | BJ4: 23834 | BK4: 13588 | BL4: 95.833333 | BM4: 93.75 | BN4: 'Number of leaves: 23\nSize of the tree: 28\n' | BO4: 28 | BP4: 23 | BQ4: 23
A5: breast-cancer | B5: 4 | C5: weka.classifiers.trees.J48 | D5: '-C 0.25 -M 2' | E5: -2.1773317e+17 | F5: 20250406 | G5: 189 | H5: 97 | I5: 70 | J5: 27 | K5: 0 | L5: 72.164948 | M5: 27.835052 | N5: 0 | O5: 0.18232907 | P5: 0.37947602 | Q5: 0.4534945 | R5: 90.576555 | S5: 99.058102 | T5: 85.362721 | U5: 84.790363 | V5: 0.57235759 | W5: 0.88002805 | X5: 0.87412746 | Y5: 0.0059005937 | Z5: 8.2442336 | AA5: 0.084992099 | AB5: 9.6578852 | AC5: 0.94117647 | AD5: 64 | AE5: 0.79310345 | AF5: 23 | AG5: 0.20689655 | AH5: 6 | AI5: 0.058823529 | AJ5: 4 | AK5: 0.73563218 | AL5: 0.94117647 | AM5: 0.82580645 | AN5: 0.22293064 | AO5: 0.60775862 | AP5: 0.75116564 | AQ5: 0.72164948 | AR5: 0.57357646 | AS5: 0.42642354 | AT5: 0.27835052 | AU5: 0.69508236 | AV5: 0.72164948 | AW5: 0.67090635 | AX5: 0.22293064 | AY5: 0.60775862 | AZ5: 0.6444558 | BA5: 0.56674938 | BB5: 0.72164948 | BC5: 0.002 | BD5: 0 | BE5: 0.001303 | BF5: 0.000368 | BG5: 1.303 | BH5: 0.368 | BI5: 5712 | BJ5: 23725 | BK5: 13697 | BL5: 100 | BM5: 100 | BN5: 'Number of leaves: 4\nSize of the tree: 6\n' | BO5: 6 | BP5: 4 | BQ5: 4
A6: breast-cancer | B6: 5 | C6: weka.classifiers.trees.J48 | D6: '-C 0.25 -M 2' | E6: -2.1773317e+17 | F6: 20250406 | G6: 189 | H6: 97 | I6: 70 | J6: 27 | K6: 0 | L6: 72.164948 | M6: 27.835052 | N6: 0 | O6: 0.14046603 | P6: 0.36806555 | Q6: 0.45360296 | R6: 87.853008 | S6: 99.081793 | T6: 85.362721 | U6: 1155.2215 | V6: -1069.8588 | W6: 0.88002805 | X6: 11.9095 | Y6: -11.029472 | Z6: 10.679089 | AA6: 0.11009371 | AB6: 12.51025 | AC6: 0.97058824 | AD6: 66 | AE6: 0.86206897 | AF6: 25 | AG6: 0.13793103 | AH6: 4 | AI6: 0.029411765 | AJ6: 2 | AK6: 0.72527473 | AL6: 0.97058824 | AM6: 0.83018868 | AN6: 0.20623577 | AO6: 0.56845842 | AP6: 0.74210319 | AQ6: 0.72164948 | AR6: 0.61313021 | AS6: 0.38686979 | AT6: 0.27835052 | AU6: 0.70775273 | AV6: 0.72164948 | AW6: 0.65032373 | AX6: 0.20623577 | AY6: 0.56845842 | AZ6: 0.63241578 | BA6: 0.52938005 | BB6: 0.72164948 | BC6: 0.002 | BD6: 0 | BE6: 0.000983 | BF6: 0.000398 | BG6: 0.983 | BH6: 0.398 | BI6: 7630 | BJ6: 23725 | BK6: 13697 | BL6: 98.969072 | BM6: 97.42268 | BN6: 'Number of leaves: 13\nSize of the tree: 17\n' | BO6: 17 | BP6: 13 | BQ6: 13
A7: breast-cancer | B7: 6 | C7: weka.classifiers.trees.J48 | D7: '-C 0.25 -M 2' | E7: -2.1773317e+17 | F7: 20250406 | G7: 189 | H7: 97 | I7: 74 | J7: 23 | K7: 0 | L7: 76.28866 | M7: 23.71134 | N7: 0 | O7: 0.33581423 | P7: 0.35194323 | Q7: 0.43142391 | R7: 84.004795 | S7: 94.237159 | T7: 85.362721 | U7: 1148.6482 | V7: -1063.2855 | W7: 0.88002805 | X7: 11.841735 | Y7: -10.961706 | Z7: 14.5783 | AA7: 0.15029176 | AB7: 17.078064 | AC7: 0.94117647 | AD7: 64 | AE7: 0.65517241 | AF7: 19 | AG7: 0.34482759 | AH7: 10 | AI7: 0.058823529 | AJ7: 4 | AK7: 0.77108434 | AL7: 0.94117647 | AM7: 0.84768212 | AN7: 0.37258261 | AO7: 0.66353955 | AP7: 0.78163328 | AQ7: 0.7628866 | AR7: 0.47688254 | AS7: 0.52311746 | AT7: 0.2371134 | AU7: 0.75410331 | AV7: 0.7628866 | AW7: 0.73330676 | AX7: 0.37258261 | AY7: 0.66353955 | AZ7: 0.69009486 | BA7: 0.6563992 | BB7: 0.7628866 | BC7: 0.001 | BD7: 0 | BE7: 0.000835 | BF7: 0.000314 | BG7: 0.835 | BH7: 0.314 | BI7: 8310 | BJ7: 23725 | BK7: 13697 | BL7: 98.969072 | BM7: 98.453608 | BN7: 'Number of leaves: 17\nSize of the tree: 21\n' | BO7: 21 | BP7: 17 | BQ7: 17
A8: breast-cancer | B8: 7 | C8: weka.classifiers.trees.J48 | D8: '-C 0.25 -M 2' | E8: -2.1773317e+17 | F8: 20250406 | G8: 188 | H8: 98 | I8: 72 | J8: 26 | K8: 0 | L8: 73.469388 | M8: 26.530612 | N8: 0 | O8: 0.20424735 | P8: 0.36811051 | Q8: 0.4438247 | R8: 87.98739 | S8: 97.229184 | T8: 85.877551 | U8: 3292.9176 | V8: -3207.0401 | W8: 0.87630154 | X8: 33.6012 | Y8: -32.724899 | Z8: 10.66592 | AA8: 0.10883592 | AB8: 12.419917 | AC8: 0.95652174 | AD8: 66 | AE8: 0.79310345 | AF8: 23 | AG8: 0.20689655 | AH8: 6 | AI8: 0.043478261 | AJ8: 3 | AK8: 0.74157303 | AL8: 0.95652174 | AM8: 0.83544304 | AN8: 0.25829021 | AO8: 0.65942029 | AP8: 0.78089044 | AQ8: 0.73469388 | AR8: 0.57127559 | AS8: 0.42872441 | AT8: 0.26530612 | AU8: 0.71940686 | AV8: 0.73469388 | AW8: 0.681668 | AX8: 0.25829021 | AY8: 0.65942029 | AZ8: 0.67830239 | BA8: 0.57561626 | BB8: 0.73469388 | BC8: 0 | BD8: 0.001 | BE8: 0.00066 | BF8: 0.000312 | BG8: 0.66 | BH8: 0.312 | BI8: 8990 | BJ8: 23616 | BK8: 13806 | BL8: 96.938776 | BM8: 96.428571 | BN8: 'Number of leaves: 21\nSize of the tree: 25\n' | BO8: 25 | BP8: 21 | BQ8: 21
A9: breast-cancer | B9: 8 | C9: weka.classifiers.trees.J48 | D9: '-C 0.25 -M 2' | E9: -2.1773317e+17 | F9: 20250406 | G9: 188 | H9: 98 | I9: 69 | J9: 29 | K9: 0 | L9: 70.408163 | M9: 29.591837 | N9: 0 | O9: 0.21965953 | P9: 0.38218374 | Q9: 0.48205378 | R9: 91.351236 | S9: 105.60407 | T9: 85.877551 | U9: 2235.8061 | V9: -2149.9285 | W9: 0.87630154 | X9: 22.814348 | Y9: -21.938046 | Z9: 5.2980937 | AA9: 0.05406218 | AB9: 6.1693581 | AC9: 0.85507246 | AD9: 59 | AE9: 0.65517241 | AF9: 19 | AG9: 0.34482759 | AH9: 10 | AI9: 0.14492754 | AJ9: 10 | AK9: 0.75641026 | AL9: 0.85507246 | AM9: 0.80272109 | AN9: 0.22639881 | AO9: 0.50324838 | AP9: 0.69869849 | AQ9: 0.70408163 | AR9: 0.50418158 | AS9: 0.49581842 | AT9: 0.29591837 | AU9: 0.68053375 | AV9: 0.70408163 | AW9: 0.68596418 | AX9: 0.22639881 | AY9: 0.50324838 | AZ9: 0.60394826 | BA9: 0.60544218 | BB9: 0.70408163 | BC9: 0 | BD9: 0.001 | BE9: 0.000609 | BF9: 0.000321 | BG9: 0.609 | BH9: 0.321 | BI9: 8140 | BJ9: 23616 | BK9: 13806 | BL9: 97.959184 | BM9: 98.469388 | BN9: 'Number of leaves: 16\nSize of the tree: 20\n' | BO9: 20 | BP9: 16 | BQ9: 16
A10: breast-cancer | B10: 9 | C10: weka.classifiers.trees.J48 | D10: '-C 0.25 -M 2' | E10: -2.1773317e+17 | F10: 20250406 | G10: 189 | H10: 97 | I10: 71 | J10: 26 | K10: 0 | L10: 73.195876 | M10: 26.804124 | N10: 0 | O10: 0.20290771 | P10: 0.37523825 | Q10: 0.44082485 | R10: 89.565049 | S10: 96.290634 | T10: 85.362721 | U10: 80.749431 | V10: 4.6132902 | W10: 0.88002805 | X10: 0.83246836 | Y10: 0.047559693 | Z10: 9.5191888 | AA10: 0.098135967 | AB10: 11.151459 | AC10: 0.95588235 | AD10: 65 | AE10: 0.79310345 | AF10: 23 | AG10: 0.20689655 | AH10: 6 | AI10: 0.044117647 | AJ10: 3 | AK10: 0.73863636 | AL10: 0.95588235 | AM10: 0.83333333 | AN10: 0.25685557 | AO10: 0.60243408 | AP10: 0.7475176 | AQ10: 0.73195876 | AR10: 0.56917986 | AS10: 0.43082014 | AT10: 0.26804124 | AU10: 0.71711965 | AV10: 0.73195876 | AW10: 0.67860373 | AX10: 0.25685557 | AY10: 0.60243408 | AZ10: 0.64488078 | BA10: 0.5745614 | BB10: 0.73195876 | BC10: 0.001 | BD10: 0 | BE10: 0.000631 | BF10: 0.000167 | BG10: 0.631 | BH10: 0.167 | BI10: 5542 | BJ10: 23725 | BK10: 13697 | BL10: 100 | BM10: 100 | BN10: 'Number of leaves: 3\nSize of the tree: 5\n' | BO10: 5 | BP10: 3 | BQ10: 3
A11: breast-cancer | B11: 10 | C11: weka.classifiers.trees.J48 | D11: '-C 0.25 -M 2' | E11: -2.1773317e+17 | F11: 20250406 | G11: 188 | H11: 98 | I11: 72 | J11: 26 | K11: 0 | L11: 73.469388 | M11: 26.530612 | N11: 0 | O11: 0.20424735 | P11: 0.36089343 | Q11: 0.44975256 | R11: 86.262331 | S11: 98.527805 | T11: 85.877551 | U11: 3294.6712 | V11: -3208.7937 | W11: 0.87630154 | X11: 33.619094 | Y11: -32.742792 | Z11: 12.356737 | AA11: 0.12608915 | AB11: 14.388786 | AC11: 0.95652174 | AD11: 66 | AE11: 0.79310345 | AF11: 23 | AG11: 0.20689655 | AH11: 6 | AI11: 0.043478261 | AJ11: 3 | AK11: 0.74157303 | AL11: 0.95652174 | AM11: 0.83544304 | AN11: 0.25829021 | AO11: 0.6051974 | AP11: 0.74547574 | AQ11: 0.73469388 | AR11: 0.57127559 | AS11: 0.42872441 | AT11: 0.26530612 | AU11: 0.71940686 | AV11: 0.73469388 | AW11: 0.681668 | AX11: 0.25829021 | AY11: 0.6051974 | AZ11: 0.6442256 | BA11: 0.57561626 | BB11: 0.73469388 | BC11: 0.001 | BD11: 0 | BE11: 0.000622 | BF11: 0.000102 | BG11: 0.622 | BH11: 0.102 | BI11: 7630 | BJ11: 23616 | BK11: 13806 | BL11: 96.938776 | BM11: 95.408163 | BN11: 'Number of leaves: 13\nSize of the tree: 17\n' | BO11: 17 | BP11: 13 | BQ11: 13
A12: breast-cancer | B12: 11 | C12: weka.classifiers.trees.J48 | D12: '-C 0.25 -M 2' | E12: -2.1773317e+17 | F12: 20250406 | G12: 189 | H12: 97 | I12: 67 | J12: 30 | K12: 0 | L12: 69.072165 | M12: 30.927835 | N12: 0 | O12: 0.18120428 | P12: 0.36882609 | Q12: 0.46783913 | R12: 88.034539 | S12: 102.19144 | T12: 85.362721 | U12: 1159.6908 | V12: -1074.3281 | W12: 0.88002805 | X12: 11.955575 | Y12: -11.075547 | Z12: 8.6441882 | AA12: 0.089115342 | AB12: 10.126421 | AC12: 0.85294118 | AD12: 58 | AE12: 0.68965517 | AF12: 20 | AG12: 0.31034483 | AH12: 9 | AI12: 0.14705882 | AJ12: 10 | AK12: 0.74358974 | AL12: 0.85294118 | AM12: 0.79452055 | AN12: 0.1883555 | AO12: 0.58924949 | AP12: 0.74994736 | AQ12: 0.69072165 | AR12: 0.52743565 | AS12: 0.47256435 | AT12: 0.30927835 | AU12: 0.66289634 | AV12: 0.69072165 | AW12: 0.66909688 | AX12: 0.1883555 | AY12: 0.58924949 | AZ12: 0.64911997 | BA12: 0.58476027 | BB12: 0.69072165 | BC12: 0 | BD12: 0 | BE12: 0.000353 | BF12: 8.6e-05 | BG12: 0.353 | BH12: 0.086 | BI12: 9014 | BJ12: 23725 | BK12: 13697 | BL12: 98.969072 | BM12: 97.42268 | BN12: 'Number of leaves: 20\nSize of the tree: 25\n' | BO12: 25 | BP12: 20 | BQ12: 20
A13: breast-cancer | B13: 12 | C13: weka.classifiers.trees.J48 | D13: '-C 0.25 -M 2' | E13: -2.1773317e+17 | F13: 20250406 | G13: 189 | H13: 97 | I13: 73 | J13: 24 | K13: 0 | L13: 75.257732 | M13: 24.742268 | N13: 0 | O13: 0.29879518 | P13: 0.37358239 | Q13: 0.42827987 | R13: 89.169814 | S13: 93.550398 | T13: 85.362721 | U13: 77.333032 | V13: 8.0296887 | W13: 0.88002805 | X13: 0.79724775 | Y13: 0.082780296 | Z13: 10.724292 | AA13: 0.11055971 | AB13: 12.563203 | AC13: 0.94117647 | AD13: 64 | AE13: 0.68965517 | AF13: 20 | AG13: 0.31034483 | AH13: 9 | AI13: 0.058823529 | AJ13: 4 | AK13: 0.76190476 | AL13: 0.94117647 | AM13: 0.84210526 | AN13: 0.33800016 | AO13: 0.65415822 | AP13: 0.77360279 | AQ13: 0.75257732 | AR13: 0.50105602 | AS13: 0.49894398 | AT13: 0.24742268 | AU13: 0.74109739 | AV13: 0.75257732 | AW13: 0.71847144 | AX13: 0.33800016 | AY13: 0.65415822 | AZ13: 0.67750756 | BA13: 0.63533835 | BB13: 0.75257732 | BC13: 0 | BD13: 0 | BE13: 0.000518 | BF13: 7.7e-05 | BG13: 0.518 | BH13: 0.077 | BI13: 5542 | BJ13: 23725 | BK13: 13697 | BL13: 100 | BM13: 100 | BN13: 'Number of leaves: 3\nSize of the tree: 5\n' | BO13: 5 | BP13: 3 | BQ13: 3
... A31: breast-cancer | B31: 30 | C31: weka.classifiers.trees.J48 | D31: '-C 0.25 -M 2' | E31: -2.1773317e+17 | F31: 20250406 | G31: 189 | H31: 97 | I31: 64 | J31: 33 | K31: 0 | L31: 65.979381 | M31: 34.020619 | N31: 0 | O31: 0.02438281 | P31: 0.39377327 | Q31: 0.48201808 | R31: 93.989144 | S31: 105.28859 | T31: 85.362721 | U31: 93.959782 | V31: -8.5970612 | W31: 0.88002805 | X31: 0.96865755 | Y31: -0.088629497 | Z31: 3.4781664 | AA31: 0.035857386 | AB31: 4.0745731 | AC31: 0.88235294 | AD31: 60 | AE31: 0.86206897 | AF31: 25 | AG31: 0.13793103 | AH31: 4 | AI31: 0.11764706 | AJ31: 8 | AK31: 0.70588235 | AL31: 0.88235294 | AM31: 0.78431373 | AN31: 0.028203724 | AO31: 0.61688641 | AP31: 0.76665072 | AQ31: 0.65979381 | AR31: 0.63950984 | AS31: 0.36049016 | AT31: 0.34020619 | AU31: 0.59450172 | AV31: 0.65979381 | AW31: 0.60816361 | AX31: 0.028203724 | AY31: 0.61688641 | AZ31: 0.64530556 | BA31: 0.48971784 | BB31: 0.65979381 | BC31: 0 | BD31: 0.001 | BE31: 0.000429 | BF31: 8.9e-05 | BG31: 0.429 | BH31: 0.089 | BI31: 7946 | BJ31: 23725 | BK31: 13697 | BL31: 100 | BM31: 100 | BN31: 'Number of leaves: 16\nSize of the tree: 19\n' | BO31: 19 | BP31: 16 | BQ31: 16
A32: breast-cancer | B32: 1 | C32: weka.classifiers.functions.MultilayerPerceptron | D32: '-L 0.3 -M 0.2 -N 500 -V 0 -S 0 -E 20 -H a' | E32: -5.9906078e+18 | F32: 20250406 | G32: 190 | H32: 96 | I32: 70 | J32: 26 | K32: 0 | L32: 72.916667 | M32: 27.083333 | N32: 0 | O32: 0.28440367 | P32: 0.2959712 | Q32: 0.49130151 | R32: 70.88541 | S32: 108.06171 | T32: 83.638867 | U32: 215.45598 | V32: -131.81711 | W32: 0.8712382 | X32: 2.2443331 | Y32: -1.3730949 | Z32: 19.898612 | AA32: 0.20727721 | AB32: 23.791106 | AC32: 0.86764706 | AD32: 59 | AE32: 0.60714286 | AF32: 17 | AG32: 0.39285714 | AH32: 11 | AI32: 0.13235294 | AJ32: 9 | AK32: 0.77631579 | AL32: 0.86764706 | AM32: 0.81944444 | AN32: 0.29155897 | AO32: 0.6302521 | AP32: 0.77603909 | AQ32: 0.72916667 | AR32: 0.46866246 | AS32: 0.53133754 | AT32: 0.27083333 | AU32: 0.71030702 | AV32: 0.72916667 | AW32: 0.71412037 | AX32: 0.29155897 | AY32: 0.6302521 | AZ32: 0.68878102 | BA32: 0.63888889 | BB32: 0.72916667 | BC32: 1.266 | BD32: 0.002 | BE32: 1.258438 | BF32: 0.001415 | BG32: 1258.438 | BH32: 1.415 | BI32: 86241 | BJ32: 23834 | BK32: 13588 | BL32: 83.333333 | BM32: 64.0625 | BN32: ? | BO32: ? | BP32: ? | BQ32: ?
A33: breast-cancer | B33: 2 | C33: weka.classifiers.functions.MultilayerPerceptron | D33: '-L 0.3 -M 0.2 -N 500 -V 0 -S 0 -E 20 -H a' | E33: -5.9906078e+18 | F33: 20250406 | G33: 188 | H33: 98 | I33: 66 | J33: 32 | K33: 0 | L33: 67.346939 | M33: 32.653061 | N33: 0 | O33: 0.18375846 | P33: 0.32595887 | Q33: 0.5260377 | R33: 77.91212 | S33: 115.23968 | T33: 85.877551 | U33: 186.34921 | V33: -100.47166 | W33: 0.87630154 | X33: 1.9015225 | Y33: -1.025221 | Z33: 14.000989 | AA33: 0.14286724 | AB33: 16.303433 | AC33: 0.79710145 | AD33: 55 | AE33: 0.62068966 | AF33: 18 | AG33: 0.37931034 | AH33: 11 | AI33: 0.20289855 | AJ33: 14 | AK33: 0.75342466 | AL33: 0.79710145 | AM33: 0.77464789 | AN33: 0.18472247 | AO33: 0.64317841 | AP33: 0.79425424 | AQ33: 0.67346939 | AR33: 0.49705759 | AS33: 0.50294241 | AT33: 0.32653061 | AU33: 0.66067654 | AV33: 0.67346939 | AW33: 0.66597468 | AX33: 0.18472247 | AY33: 0.64317841 | AZ33: 0.69837284 | BA33: 0.59102765 | BB33: 0.67346939 | BC33: 1.243 | BD33: 0.001 | BE33: 1.237338 | BF33: 0.001306 | BG33: 1237.338 | BH33: 1.306 | BI33: 86241 | BJ33: 23616 | BK33: 13806 | BL33: 83.673469 | BM33: 65.816327 | BN33: ? | BO33: ? | BP33: ? | BQ33: ?
A34: breast-cancer | B34: 3 | C34: weka.classifiers.functions.MultilayerPerceptron | D34: '-L 0.3 -M 0.2 -N 500 -V 0 -S 0 -E 20 -H a' | E34: -5.9906078e+18 | F34: 20250406 | G34: 190 | H34: 96 | I34: 65 | J34: 31 | K34: 0 | L34: 67.708333 | M34: 32.291667 | N34: 0 | O34: 0.25748503 | P34: 0.32850732 | Q34: 0.52666601 | R34: 78.677845 | S34: 115.84013 | T34: 83.638867 | U34: 204.8783 | V34: -121.23943 | W34: 0.8712382 | X34: 2.134149 | Y34: -1.2629108 | Z34: 13.32836 | AA34: 0.13883709 | AB34: 15.935606 | AC34: 0.73529412 | AD34: 50 | AE34: 0.46428571 | AF34: 13 | AG34: 0.53571429 | AH34: 15 | AI34: 0.26470588 | AJ34: 18 | AK34: 0.79365079 | AL34: 0.73529412 | AM34: 0.76335878 | AN34: 0.25935163 | AO34: 0.64180672 | AP34: 0.8006528 | AQ34: 0.67708333 | AR34: 0.40607493 | AS34: 0.59392507 | AT34: 0.32291667 | AU34: 0.69474507 | AV34: 0.67708333 | AW34: 0.68415509 | AX34: 0.25935163 | AY34: 0.64180672 | AZ34: 0.68660799 | BA34: 0.62758103 | BB34: 0.67708333 | BC34: 1.333 | BD34: 0.002 | BE34: 1.320214 | BF34: 0.001095 | BG34: 1320.214 | BH34: 1.095 | BI34: 86241 | BJ34: 23834 | BK34: 13588 | BL34: 80.208333 | BM34: 63.020833 | BN34: ? | BO34: ? | BP34: ? | BQ34: ?
A35: breast-cancer | B35: 4 | C35: weka.classifiers.functions.MultilayerPerceptron | D35: '-L 0.3 -M 0.2 -N 500 -V 0 -S 0 -E 20 -H a' | E35: -5.9906078e+18 | F35: 20250406 | G35: 189 | H35: 97 | I35: 66 | J35: 31 | K35: 0 | L35: 68.041237 | M35: 31.958763 | N35: 0 | O35: 0.14452347 | P35: 0.326769 | Q35: 0.51074896 | R35: 77.995998 | S35: 111.56436 | T35: 85.362721 | U35: 176.1039 | V35: -90.741179 | W35: 0.88002805 | X35: 1.8155041 | Y35: -0.93547607 | Z35: 14.029009 | AA35: 0.14462896 | AB35: 16.434585 | AC35: 0.85294118 | AD35: 58 | AE35: 0.72413793 | AF35: 21 | AG35: 0.27586207 | AH35: 8 | AI35: 0.14705882 | AJ35: 10 | AK35: 0.73417722 | AL35: 0.85294118 | AM35: 0.78911565 | AN35: 0.15168075 | AO35: 0.60218053 | AP35: 0.77787383 | AQ35: 0.68041237 | AR35: 0.55160913 | AS35: 0.44839087 | AT35: 0.31958763 | AU35: 0.64755608 | AV35: 0.68041237 | AW35: 0.65497118 | AX35: 0.15168075 | AY35: 0.60218053 | AZ35: 0.70228085 | BA35: 0.56477059 | BB35: 0.68041237 | BC35: 1.381 | BD35: 0.001 | BE35: 1.312401 | BF35: 0.001033 | BG35: 1312.401 | BH35: 1.033 | BI35: 86241 | BJ35: 23725 | BK35: 13697 | BL35: 83.505155 | BM35: 68.041237 | BN35: ? | BO35: ? | BP35: ? | BQ35: ?
A36: breast-cancer | B36: 5 | C36: weka.classifiers.functions.MultilayerPerceptron | D36: '-L 0.3 -M 0.2 -N 500 -V 0 -S 0 -E 20 -H a' | E36: -5.9906078e+18 | F36: 20250406 | G36: 189 | H36: 97 | I36: 65 | J36: 32 | K36: 0 | L36: 67.010309 | M36: 32.989691 | N36: 0 | O36: 0.19710295 | P36: 0.33895015 | Q36: 0.54524844 | R36: 80.903496 | S36: 119.10018 | T36: 85.362721 | U36: 191.90658 | V36: -106.54386 | W36: 0.88002805 | X36: 1.9784184 | Y36: -1.0983903 | Z36: 11.473341 | AA36: 0.11828187 | AB36: 13.440693 | AC36: 0.77941176 | AD36: 53 | AE36: 0.5862069 | AF36: 17 | AG36: 0.4137931 | AH36: 12 | AI36: 0.22058824 | AJ36: 15 | AK36: 0.75714286 | AL36: 0.77941176 | AM36: 0.76811594 | AN36: 0.19735158 | AO36: 0.64477688 | AP36: 0.82097154 | AQ36: 0.67010309 | AR36: 0.47689822 | AS36: 0.52310178 | AT36: 0.32989691 | AU36: 0.6636557 | AV36: 0.67010309 | AW36: 0.66660263 | AX36: 0.19735158 | AY36: 0.64477688 | AZ36: 0.71192561 | BA36: 0.59834369 | BB36: 0.67010309 | BC36: 1.341 | BD36: 0.001 | BE36: 1.322218 | BF36: 0.001001 | BG36: 1322.218 | BH36: 1.001 | BI36: 86241 | BJ36: 23725 | BK36: 13697 | BL36: 78.350515 | BM36: 61.85567 | BN36: ? | BO36: ? | BP36: ? | BQ36: ?
A37: breast-cancer | B37: 6 | C37: weka.classifiers.functions.MultilayerPerceptron | D37: '-L 0.3 -M 0.2 -N 500 -V 0 -S 0 -E 20 -H a' | E37: -5.9906078e+18 | F37: 20250406 | G37: 189 | H37: 97 | I37: 65 | J37: 32 | K37: 0 | L37: 67.010309 | M37: 32.989691 | N37: 0 | O37: 0.22824465 | P37: 0.32482775 | Q37: 0.519423 | R37: 77.532642 | S37: 113.45905 | T37: 85.362721 | U37: 179.0585 | V37: -93.695774 | W37: 0.88002805 | X37: 1.8459639 | Y37: -0.96593582 | Z37: 14.678205 | AA37: 0.1513217 | AB37: 17.195099 | AC37: 0.75 | AD37: 51 | AE37: 0.51724138 | AF37: 15 | AG37: 0.48275862 | AH37: 14 | AI37: 0.25 | AJ37: 17 | AK37: 0.77272727 | AL37: 0.75 | AM37: 0.76119403 | AN37: 0.22851063 | AO37: 0.663286 | AP37: 0.82509264 | AQ37: 0.67010309 | AR37: 0.43734447 | AS37: 0.56265553 | AT37: 0.32989691 | AU37: 0.67672401 | AV37: 0.67010309 | AW37: 0.67313946 | AX37: 0.22851063 | AY37: 0.663286 | AZ37: 0.72511654 | BA37: 0.61393035 | BB37: 0.67010309 | BC37: 1.351 | BD37: 0.001 | BE37: 1.342474 | BF37: 0.000953 | BG37: 1342.474 | BH37: 0.953 | BI37: 86241 | BJ37: 23725 | BK37: 13697 | BL37: 82.474227 | BM37: 67.010309 | BN37: ? | BO37: ? | BP37: ? | BQ37: ?
A38: breast-cancer | B38: 7 | C38: weka.classifiers.functions.MultilayerPerceptron | D38: '-L 0.3 -M 0.2 -N 500 -V 0 -S 0 -E 20 -H a' | E38: -5.9906078e+18 | F38: 20250406 | G38: 188 | H38: 98 | I38: 62 | J38: 36 | K38: 0 | L38: 63.265306 | M38: 36.734694 | N38: 0 | O38: 0.081728267 | P38: 0.38540996 | Q38: 0.56913577 | R38: 92.122382 | S38: 124.68122 | T38: 85.877551 | U38: 213.20018 | V38: -127.32263 | W38: 0.87630154 | X38: 2.1755121 | Y38: -1.2992105 | Z38: 1.5765138 | AA38: 0.016086875 | AB38: 1.8357694 | AC38: 0.76811594 | AD38: 53 | AE38: 0.68965517 | AF38: 20 | AG38: 0.31034483 | AH38: 9 | AI38: 0.23188406 | AJ38: 16 | AK38: 0.7260274 | AL38: 0.76811594 | AM38: 0.74647887 | AN38: 0.082157019 | AO38: 0.56046977 | AP38: 0.74534867 | AQ38: 0.63265306 | AR38: 0.55419229 | AS38: 0.44580771 | AT38: 0.36734694 | AU38: 0.61771317 | AV38: 0.63265306 | AW38: 0.62422152 | AX38: 0.082157019 | AY38: 0.56046977 | AZ38: 0.64706902 | BA38: 0.5399061 | BB38: 0.63265306 | BC38: 1.341 | BD38: 0.001 | BE38: 1.32904 | BF38: 0.000957 | BG38: 1329.04 | BH38: 0.957 | BI38: 86241 | BJ38: 23616 | BK38: 13806 | BL38: 79.591837 | BM38: 68.877551 | BN38: ? | BO38: ? | BP38: ? | BQ38: ?
A39: breast-cancer | B39: 8 | C39: weka.classifiers.functions.MultilayerPerceptron | D39: '-L 0.3 -M 0.2 -N 500 -V 0 -S 0 -E 20 -H a' | E39: -5.9906078e+18 | F39: 20250406 | G39: 188 | H39: 98 | I39: 67 | J39: 31 | K39: 0 | L39: 68.367347 | M39: 31.632653 | N39: 0 | O39: 0.23321555 | P39: 0.34141954 | Q39: 0.51989114 | R39: 81.607598 | S39: 113.89314 | T39: 85.877551 | U39: 217.31105 | V39: -131.4335 | W39: 0.87630154 | X39: 2.2174597 | Y39: -1.3411582 | Z39: 10.889433 | AA39: 0.11111667 | AB39: 12.680186 | AC39: 0.7826087 | AD39: 54 | AE39: 0.55172414 | AF39: 16 | AG39: 0.44827586 | AH39: 13 | AI39: 0.2173913 | AJ39: 15 | AK39: 0.77142857 | AL39: 0.7826087 | AM39: 0.77697842 | AN39: 0.23328692 | AO39: 0.62218891 | AP39: 0.78882473 | AQ39: 0.68367347 | AR39: 0.45278891 | AS39: 0.54721109 | AT39: 0.31632653 | AU39: 0.68053936 | AV39: 0.68367347 | AW39: 0.68203654 | AX39: 0.23328692 | AY39: 0.62218891 | AZ39: 0.69111421 | BA39: 0.61655938 | BB39: 0.68367347 | BC39: 1.301 | BD39: 0 | BE39: 1.293515 | BF39: 0.000941 | BG39: 1293.515 | BH39: 0.941 | BI39: 86241 | BJ39: 23616 | BK39: 13806 | BL39: 82.653061 | BM39: 70.408163 | BN39: ? | BO39: ? | BP39: ? | BQ39: ?
A40: breast-cancer | B40: 9 | C40: weka.classifiers.functions.MultilayerPerceptron | D40: '-L 0.3 -M 0.2 -N 500 -V 0 -S 0 -E 20 -H a' | E40: -5.9906078e+18 | F40: 20250406 | G40: 189 | H40: 97 | I40: 67 | J40: 30 | K40: 0 | L40: 69.072165 | M40: 30.927835 | N40: 0 | O40: 0.26217039 | P40: 0.31276134 | Q40: 0.51411177 | R40: 74.65253 | S40: 112.29891 | T40: 85.362721 | U40: 188.0594 | V40: -102.69668 | W40: 0.88002805 | X40: 1.9387567 | Y40: -1.0587287 | Z40: 17.557218 | AA40: 0.18100225 | AB40: 20.567782 | AC40: 0.77941176 | AD40: 53 | AE40: 0.51724138 | AF40: 15 | AG40: 0.48275862 | AH40: 14 | AI40: 0.22058824 | AJ40: 15 | AK40: 0.77941176 | AL40: 0.77941176 | AM40: 0.77941176 | AN40: 0.26217039 | AO40: 0.62829615 | AP40: 0.786134 | AQ40: 0.69072165 | AR40: 0.42855126 | AS40: 0.57144874 | AT40: 0.30927835 | AU40: 0.69072165 | AV40: 0.69072165 | AW40: 0.69072165 | AX40: 0.26217039 | AY40: 0.62829615 | AZ40: 0.7042014 | BA40: 0.63108519 | BB40: 0.69072165 | BC40: 1.49 | BD40: 0.001 | BE40: 1.359222 | BF40: 0.000973 | BG40: 1359.222 | BH40: 0.973 | BI40: 86241 | BJ40: 23725 | BK40: 13697 | BL40: 79.381443 | BM40: 63.917526 | BN40: ? | BO40: ? | BP40: ? | BQ40: ?
A41: breast-cancer | B41: 10 | C41: weka.classifiers.functions.MultilayerPerceptron | D41: '-L 0.3 -M 0.2 -N 500 -V 0 -S 0 -E 20 -H a' | E41: -5.9906078e+18 | F41: 20250406 | G41: 188 | H41: 98 | I41: 65 | J41: 33 | K41: 0 | L41: 66.326531 | M41: 33.673469 | N41: 0 | O41: 0.13111231 | P41: 0.35423558 | Q41: 0.55700128 | R41: 84.670943 | S41: 122.02291 | T41: 85.877551 | U41: 241.05279 | V41: -155.17524 | W41: 0.87630154 | X41: 2.4597224 | Y41: -1.5834208 | Z41: 8.3213923 | AA41: 0.084912166 | AB41: 9.6898341 | AC41: 0.8115942 | AD41: 56 | AE41: 0.68965517 | AF41: 20 | AG41: 0.31034483 | AH41: 9 | AI41: 0.1884058 | AJ41: 13 | AK41: 0.73684211 | AL41: 0.8115942 | AM41: 0.77241379 | AN41: 0.13339764 | AO41: 0.57521239 | AP41: 0.7780903 | AQ41: 0.66326531 | AR41: 0.54132628 | AS41: 0.45867372 | AT41: 0.33673469 | AU41: 0.63985451 | AV41: 0.66326531 | AW41: 0.64828414 | AX41: 0.13339764 | AY41: 0.57521239 | AZ41: 0.67088708 | BA41: 0.56267748 | BB41: 0.66326531 | BC41: 1.45 | BD41: 0.001 | BE41: 1.354642 | BF41: 0.001002 | BG41: 1354.642 | BH41: 1.002 | BI41: 86241 | BJ41: 23616 | BK41: 13806 | BL41: 77.55102 | BM41: 62.755102 | BN41: ? | BO41: ? | BP41: ? | BQ41: ?
A42: breast-cancer | B42: 11 | C42: weka.classifiers.functions.MultilayerPerceptron | D42: '-L 0.3 -M 0.2 -N 500 -V 0 -S 0 -E 20 -H a' | E42: -5.9906078e+18 | F42: 20250406 | G42: 189 | H42: 97 | I42: 64 | J42: 33 | K42: 0 | L42: 65.979381 | M42: 34.020619 | N42: 0 | O42: 0.14617231 | P42: 0.36137525 | Q42: 0.54681208 | R42: 86.25611 | S42: 119.44173 | T42: 85.362721 | U42: 200.73188 | V42: -115.36916 | W42: 0.88002805 | X42: 2.0694008 | Y42: -1.1893728 | Z42: 6.3189923 | AA42: 0.06514425 | AB42: 7.4025198 | AC42: 0.79411765 | AD42: 54 | AE42: 0.65517241 | AF42: 19 | AG42: 0.34482759 | AH42: 10 | AI42: 0.20588235 | AJ42: 14 | AK42: 0.73972603 | AL42: 0.79411765 | AM42: 0.76595745 | AN42: 0.14741106 | AO42: 0.60192698 | AP42: 0.77939202 | AQ42: 0.65979381 | AR42: 0.52084858 | AS42: 0.47915142 | AT42: 0.34020619 | AU42: 0.64314127 | AV42: 0.65979381 | AW42: 0.64977838 | AX42: 0.14741106 | AY42: 0.60192698 | AZ42: 0.68481597 | BA42: 0.57165797 | BB42: 0.65979381 | BC42: 1.346 | BD42: 0.001 | BE42: 1.32772 | BF42: 0.000993 | BG42: 1327.72 | BH42: 0.993 | BI42: 86241 | BJ42: 23725 | BK42: 13697 | BL42: 79.381443 | BM42: 67.525773 | BN42: ? | BO42: ? | BP42: ? | BQ42: ?
A43: breast-cancer | B43: 12 | C43: weka.classifiers.functions.MultilayerPerceptron | D43: '-L 0.3 -M 0.2 -N 500 -V 0 -S 0 -E 20 -H a' | E43: -5.9906078e+18 | F43: 20250406 | G43: 189 | H43: 97 | I43: 67 | J43: 30 | K43: 0 | L43: 69.072165 | M43: 30.927835 | N43: 0 | O43: 0.27647936 | P43: 0.32393551 | Q43: 0.50579232 | R43: 77.319676 | S43: 110.48166 | T43: 85.362721 | U43: 165.63407 | V43: -80.271345 | W43: 0.88002805 | X43: 1.7075677 | Y43: -0.82753964 | Z43: 14.922316 | AA43: 0.15383831 | AB43: 17.481069 | AC43: 0.76470588 | AD43: 52 | AE43: 0.48275862 | AF43: 14 | AG43: 0.51724138 | AH43: 15 | AI43: 0.23529412 | AJ43: 16 | AK43: 0.78787879 | AL43: 0.76470588 | AM43: 0.7761194 | AN43: 0.27680155 | AO43: 0.66506085 | AP43: 0.81403733 | AQ43: 0.69072165 | AR43: 0.40877439 | AS43: 0.59122561 | AT43: 0.30927835 | AU43: 0.69698985 | AV43: 0.69072165 | AW43: 0.69356824 | AX43: 0.27680155 | AY43: 0.66506085 | AZ43: 0.72911961 | BA43: 0.6380597 | BB43: 0.69072165 | BC43: 1.351 | BD43: 0.001 | BE43: 1.332848 | BF43: 0.000966 | BG43: 1332.848 | BH43: 0.966 | BI43: 86241 | BJ43: 23725 | BK43: 13697 | BL43: 86.597938 | BM43: 69.072165 | BN43: ? | BO43: ? | BP43: ? | BQ43: ?
... A61: breast-cancer | B61: 30 | C61: weka.classifiers.functions.MultilayerPerceptron | D61: '-L 0.3 -M 0.2 -N 500 -V 0 -S 0 -E 20 -H a' | E61: -5.9906078e+18 | F61: 20250406 | G61: 189 | H61: 97 | I61: 68 | J61: 29 | K61: 0 | L61: 70.103093 | M61: 29.896907 | N61: 0 | O61: 0.2649595 | P61: 0.31335483 | Q61: 0.50086286 | R61: 74.794189 | S61: 109.40491 | T61: 85.362721 | U61: 171.83427 | V61: -86.471549 | W61: 0.88002805 | X61: 1.7714873 | Y61: -0.89145927 | Z61: 18.214715 | AA61: 0.18778057 | AB61: 21.338021 | AC61: 0.80882353 | AD61: 55 | AE61: 0.55172414 | AF61: 16 | AG61: 0.44827586 | AH61: 13 | AI61: 0.19117647 | AJ61: 13 | AK61: 0.77464789 | AL61: 0.80882353 | AM61: 0.79136691 | AN61: 0.26572882 | AO61: 0.63184584 | AP61: 0.75438309 | AQ61: 0.70103093 | AR61: 0.44393154 | AS61: 0.55606846 | AT61: 0.29896907 | AU61: 0.69253666 | AV61: 0.70103093 | AW61: 0.69610351 | AX61: 0.26572882 | AY61: 0.63184584 | AZ61: 0.67606307 | BA61: 0.63204709 | BB61: 0.70103093 | BC61: 1.424 | BD61: 0.001 | BE61: 1.349343 | BF61: 0.000889 | BG61: 1349.343 | BH61: 0.889 | BI61: 86241 | BJ61: 23725 | BK61: 13697 | BL61: 84.536082 | BM61: 69.072165 | BN61: ? | BO61: ? | BP61: ? | BQ61: ?

Sheet T-Test
A1: t-Test: Paired Two Sample for Means
A3: Column1 | B3: J48 | C3: MLP
A4: Mean | B4: 71.126803 | C4: 67.556653
A5: Variance | B5: 11.939971 | C5: 12.459966
A6: Observations | B6: 30 | C6: 30
A7: Pearson Correlation | B7: 0.42139535
A8: Hypothesized Mean Difference | B8: 0
A9: df | B9: 29
A10: t Stat | B10: 5.2038632
A11: P(T<=t) one-tail | B11: 7.1966327e-06
A12: t Critical one-tail | B12: 1.699127
A13: P(T<=t) two-tail | B13: 1.4393265e-05
A14: t Critical two-tail | B14: 2.0452296

Sheet Graphs

Sheet Accuracy Analysis
A1: Key_Runs | B1: J_48 | C1: MLP | D1: Difference
A2: 1 | B2: =breast_cancer_experiment_result!L2 -> 73.958333 | C2: =breast_cancer_experiment_result!L32 -> 72.916667 | D2: =B2-C2 -> 1.0416667
A3: 2 | B3: =breast_cancer_experiment_result!L3 -> 63.265306 | C3: =breast_cancer_experiment_result!L33 -> 67.346939 | D3: =B3-C3 -> -4.0816327
A4: 3 | B4: =breast_cancer_experiment_result!L4 -> 71.875 | C4: =breast_cancer_experiment_result!L34 -> 67.708333 | D4: =B4-C4 -> 4.1666667
A5: 4 | B5: =breast_cancer_experiment_result!L5 -> 72.164948 | C5: =breast_cancer_experiment_result!L35 -> 68.041237 | D5: =B5-C5 -> 4.1237113
A6: 5 | B6: =breast_cancer_experiment_result!L6 -> 72.164948 | C6: =breast_cancer_experiment_result!L36 -> 67.010309 | D6: =B6-C6 -> 5.1546392
A7: 6 | B7: =breast_cancer_experiment_result!L7 -> 76.28866 | C7: =breast_cancer_experiment_result!L37 -> 67.010309 | D7: =B7-C7 -> 9.2783505
A8: 7 | B8: =breast_cancer_experiment_result!L8 -> 73.469388 | C8: =breast_cancer_experiment_result!L38 -> 63.265306 | D8: =B8-C8 -> 10.204082
A9: 8 | B9: =breast_cancer_experiment_result!L9 -> 70.408163 | C9: =breast_cancer_experiment_result!L39 -> 68.367347 | D9: =B9-C9 -> 2.0408163
A10: 9 | B10: =breast_cancer_experiment_result!L10 -> 73.195876 | C10: =breast_cancer_experiment_result!L40 -> 69.072165 | D10: =B10-C10 -> 4.1237113
A11: 10 | B11: =breast_cancer_experiment_result!L11 -> 73.469388 | C11: =breast_cancer_experiment_result!L41 -> 66.326531 | D11: =B11-C11 -> 7.1428571
A12: 11 | B12: =breast_cancer_experiment_result!L12 -> 69.072165 | C12: =breast_cancer_experiment_result!L42 -> 65.979381 | D12: =B12-C12 -> 3.0927835
A13: 12 | B13: =breast_cancer_experiment_result!L13 -> 75.257732 | C13: =breast_cancer_experiment_result!L43 -> 69.072165 | D13: =B13-C13 -> 6.185567
... A31: 30 | B31: =breast_cancer_experiment_result!L31 -> 65.979381 | C31: =breast_cancer_experiment_result!L61 -> 70.103093 | D31: =B31-C31 -> -4.1237113

Sheet Summary Statistics
A1: Model | B1: Mean Accuracy | C1: Standard Deviation (𝑺)
A2: J48 - Decision Tree Algorithim | B2: =AVERAGE('Accuracy Analysis'!B2:B31) -> 71.126803 | C2: =_xlfn.STDEV.S('Accuracy Analysis'!B2:B31) -> 3.4554264
A3: MLP - MultiLayer Perceptron | B3: =AVERAGE('Accuracy Analysis'!C2:C31) -> 67.556653 | C3: =_xlfn.STDEV.S('Accuracy Analysis'!C2:C31) -> 3.5298678

Sheet T-Dist Graph Making
A1: T-Distribution | B1: PDF
A2: -4 | B2: =_xlfn.T.DIST(A2, 'T-Test'!B9, FALSE) -> 0.00054318673
A3: =A2 +0.1 -> -3.9 | B3: =_xlfn.T.DIST(A3, 'T-Test'!B9, FALSE) -> 0.00070848251
A4: =A3 +0.1 -> -3.8 | B4: =_xlfn.T.DIST(A4, 'T-Test'!B9, FALSE) -> 0.0009221246
A5: =A4 +0.1 -> -3.7 | B5: =_xlfn.T.DIST(A5, 'T-Test'!B9, FALSE) -> 0.0011974146
A6: =A5 +0.1 -> -3.6 | B6: =_xlfn.T.DIST(A6, 'T-Test'!B9, FALSE) -> 0.0015509745
A7: =A6 +0.1 -> -3.5 | B7: =_xlfn.T.DIST(A7,'T-Test'!B9, FALSE) -> 0.0020034456 | D7: Rejection Regions
A8: =A7 +0.1 -> -3.4 | B8: =_xlfn.T.DIST(A8, 'T-Test'!B9, FALSE) -> 0.0025802849 | D8: =_xlfn.T.INV(0.975, 29) -> 2.0452296
A9: =A8 +0.1 -> -3.3 | B9: =_xlfn.T.DIST(A9, 'T-Test'!B9, FALSE) -> 0.0033126558
A10: =A9 +0.1 -> -3.2 | B10: =_xlfn.T.DIST(A10, 'T-Test'!B9, FALSE) -> 0.0042383994
A11: =A10 +0.1 -> -3.1 | B11: =_xlfn.T.DIST(A11,'T-Test'!B9, FALSE) -> 0.0054030605
A12: =A11 +0.1 -> -3 | B12: =_xlfn.T.DIST(A12, 'T-Test'!B9, FALSE) -> 0.0068609287
A13: =A12 +0.1 -> -2.9 | B13: =_xlfn.T.DIST(A13, 'T-Test'!B9, FALSE) -> 0.0086760338
A14: =A13 +0.1 -> -2.8 | B14: =_xlfn.T.DIST(A14, 'T-Test'!B9, FALSE) -> 0.010923015
A15: =A14 +0.1 -> -2.7 | B15: =_xlfn.T.DIST(A15, 'T-Test'!B9, FALSE) -> 0.013687759
A16: =A15 +0.1 -> -2.6 | B16: =_xlfn.T.DIST(A16, 'T-Test'!B9, FALSE) -> 0.017067669
A17: =A16 +0.1 -> -2.5 | B17: =_xlfn.T.DIST(A17, 'T-Test'!B9, FALSE) -> 0.021171422
A18: =A17 +0.1 -> -2.4 | B18: =_xlfn.T.DIST(A18, 'T-Test'!B9, FALSE) -> 0.026118025
A19: =A18 +0.1 -> -2.3 | B19: =_xlfn.T.DIST(A19, 'T-Test'!B9, FALSE) -> 0.032034989
A20: =A19 +0.1 -> -2.2 | B20: =_xlfn.T.DIST(A20, 'T-Test'!B9, FALSE) -> 0.039055441
A21: =A20 +0.1 -> -2.1 | B21: =_xlfn.T.DIST(A21, 'T-Test'!B9, FALSE) -> 0.047314006
A22: =A21 +0.1 -> -2 | B22: =_xlfn.T.DIST(A22, 'T-Test'!B9, FALSE) -> 0.05694135
A23: =A22 +0.1 -> -1.9 | B23: =_xlfn.T.DIST(A23, 'T-Test'!B9, FALSE) -> 0.068057325
A24: =A23 +0.1 -> -1.8 | B24: =_xlfn.T.DIST(A24, 'T-Test'!B9, FALSE) -> 0.080762799
A25: =A24 +0.1 -> -1.7 | B25: =_xlfn.T.DIST(A25, 'T-Test'!B9, FALSE) -> 0.095130344 | F25: t stat | G25: probability
A26: =A25 +0.1 -> -1.6 | B26: =_xlfn.T.DIST(A26, 'T-Test'!B9, FALSE) -> 0.11119415 | F26: 5.2 | G26: 0 | I26: 2.04 | J26: 0
A27: =A26 +0.1 -> -1.5 | B27: =_xlfn.T.DIST(A27,'T-Test'!B9, FALSE) -> 0.12893966 | F27: 5.2 | G27: 0.4 | I27: 2.04 | J27: 0.4
A28: =A27 +0.1 -> -1.4 | B28: =_xlfn.T.DIST(A28,'T-Test'!B9, FALSE) -> 0.14829366
A29: =A28 +0.1 -> -1.3 | B29: =_xlfn.T.DIST(A29, 'T-Test'!B9, FALSE) -> 0.16911555 | F29: -5.2 | G29: 0 | I29: -2.04 | J29: 0
A30: =A29 +0.1 -> -1.2 | B30: =_xlfn.T.DIST(A30, 'T-Test'!B9, FALSE) -> 0.19119086 | F30: -5.2 | G30: 0.4 | I30: -2.04 | J30: 0.4
A31: =A30 +0.1 -> -1.1 | B31: =_xlfn.T.DIST(A31, 'T-Test'!B9, FALSE) -> 0.21422787
A32: =A31 +0.1 -> -1 | B32: =_xlfn.T.DIST(A32, 'T-Test'!B9, FALSE) -> 0.23785815
A33: =A32 +0.1 -> -0.9 | B33: =_xlfn.T.DIST(A33, 'T-Test'!B9, FALSE) -> 0.26164185
A34: =A33 +0.1 -> -0.8 | B34: =_xlfn.T.DIST(A34, 'T-Test'!B9, FALSE) -> 0.28507811
A35: =A34 +0.1 -> -0.7 | B35: =_xlfn.T.DIST(A35, 'T-Test'!B9, FALSE) -> 0.3076205
A36: =A35 +0.1 -> -0.6 | B36: =_xlfn.T.DIST(A36, 'T-Test'!B9, FALSE) -> 0.32869726
A37: =A36 +0.1 -> -0.5 | B37: =_xlfn.T.DIST(A37, 'T-Test'!B9, FALSE) -> 0.34773532
A38: =A37 +0.1 -> -0.4 | B38: =_xlfn.T.DIST(A38, 'T-Test'!B9, FALSE) -> 0.36418668
A39: =A38 +0.1 -> -0.3 | B39: =_xlfn.T.DIST(A39, 'T-Test'!B9, FALSE) -> 0.37755571
A40: =A39 +0.1 -> -0.2 | B40: =_xlfn.T.DIST(A40, 'T-Test'!B9, FALSE) -> 0.38742503
...
